Workbook

Sheet Plantas
A1: Espécie | B1: Nome comum | C1: Variedade | D1: Tipo Plantação | E1: Sementeira/Plantação | F1: Poda | G1: Floração | H1: Colheita | J1: ID | K1: Espécie | L1: Nome comum | M1: TipoCulturaID | R1: CULTURA: | S1: EspecieID | T1: Variedade | U1: CulturaID | V1: Designação
A2: Prunus domestica | B2: Ameixoeira | C2: RAINHA CLAUDIA CARANGUEJEIRA | D2: Permanente | F2: Novembro a dezembro | G2: Fevereiro a março | H2: Julho a agosto | J2: 1 | K2: {=_xlfn.UNIQUE(A2:B96)} -> Prunus domestica | L2: Ameixoeira | M2: 1 | S2: {=_xlfn.XLOOKUP(A2&B2,$K$2:$K$13&$L$2:$L$13,$J$2:$J$13)} -> 1 | T2: {=_xlfn.UNIQUE(C2:C96)} -> RAINHA CLAUDIA CARANGUEJEIRA | U2: 1 | V2: =_xlfn.CONCAT(B2," ",C2) -> Ameixoeira RAINHA CLAUDIA CARANGUEJEIRA | W2: ="INSERT INTO Cultura(CulturaID, Variedade, EspecieVegetalID, EpocaSementeiraPlantacao, EpocaPoda, EpocaFloracao, EpocaColheita) VALUES ("&U2&", '"&T2&"', "&S2&", '"&E2&"', '"&F2&"', '"&G2&"', '"&H2&"');" -> INSERT INTO Cultura(CulturaID, Variedade, EspecieVegetalID, EpocaSementeiraPlantacao, EpocaPoda, EpocaFloracao, EpocaColheita) VALUES (1, 'RAINHA CLAUDIA CARANGUEJEIRA', 1, '', 'Novembro a dezembro', 'Fevereiro a março', 'Julho a agosto'); | X2: 3
A3: Prunus domestica | B3: Ameixoeira | C3: PRESIDENT | D3: Permanente | F3: Novembro a dezembro | G3: Fevereiro a março | H3: Julho a agosto | J3: =1+J2 -> 2 | K3: Prunus armeniaca | L3: Damasqueiro | M3: 1 | S3: {=_xlfn.XLOOKUP(A3&B3,$K$2:$K$13&$L$2:$L$13,$J$2:$J$13)} -> 1 | T3: PRESIDENT | U3: 2 | V3: =_xlfn.CONCAT(B3," ",C3) -> Ameixoeira PRESIDENT | W3: ="INSERT INTO Cultura(CulturaID, Variedade, EspecieVegetalID, EpocaSementeiraPlantacao, EpocaPoda, EpocaFloracao, EpocaColheita) VALUES ("&U3&", '"&T3&"', "&S3&", '"&E3&"', '"&F3&"', '"&G3&"', '"&H3&"');" -> INSERT INTO Cultura(CulturaID, Variedade, EspecieVegetalID, EpocaSementeiraPlantacao, EpocaPoda, EpocaFloracao, EpocaColheita) VALUES (2, 'PRESIDENT', 1, '', 'Novembro a dezembro', 'Fevereiro a março', 'Julho a agosto');
A4: Prunus domestica | B4: Ameixoeira | C4: STANLEY | D4: Permanente | F4: Novembro a dezembro | G4: Fevereiro a março | H4: Julho a agosto | J4: =1+J3 -> 3 | K4: Malus domestica | L4: Macieira | M4: 1 | S4: {=_xlfn.XLOOKUP(A4&B4,$K$2:$K$13&$L$2:$L$13,$J$2:$J$13)} -> 1 | T4: STANLEY | U4: 3 | V4: =_xlfn.CONCAT(B4," ",C4) -> Ameixoeira STANLEY | W4: ="INSERT INTO Cultura(CulturaID, Variedade, EspecieVegetalID, EpocaSementeiraPlantacao, EpocaPoda, EpocaFloracao, EpocaColheita) VALUES ("&U4&", '"&T4&"', "&S4&", '"&E4&"', '"&F4&"', '"&G4&"', '"&H4&"');" -> INSERT INTO Cultura(CulturaID, Variedade, EspecieVegetalID, EpocaSementeiraPlantacao, EpocaPoda, EpocaFloracao, EpocaColheita) VALUES (3, 'STANLEY', 1, '', 'Novembro a dezembro', 'Fevereiro a março', 'Julho a agosto');
A5: Prunus domestica | B5: Ameixoeira | C5: ANGELENO | D5: Permanente | F5: Novembro a dezembro | G5: Fevereiro a março | H5: Julho a agosto | J5: =1+J4 -> 4 | K5: Pyrus pyrifolia | L5: Pera Nashi | M5: 1 | S5: {=_xlfn.XLOOKUP(A5&B5,$K$2:$K$13&$L$2:$L$13,$J$2:$J$13)} -> 1 | T5: ANGELENO | U5: 4 | V5: =_xlfn.CONCAT(B5," ",C5) -> Ameixoeira ANGELENO | W5: ="INSERT INTO Cultura(CulturaID, Variedade, EspecieVegetalID, EpocaSementeiraPlantacao, EpocaPoda, EpocaFloracao, EpocaColheita) VALUES ("&U5&", '"&T5&"', "&S5&", '"&E5&"', '"&F5&"', '"&G5&"', '"&H5&"');" -> INSERT INTO Cultura(CulturaID, Variedade, EspecieVegetalID, EpocaSementeiraPlantacao, EpocaPoda, EpocaFloracao, EpocaColheita) VALUES (4, 'ANGELENO', 1, '', 'Novembro a dezembro', 'Fevereiro a março', 'Julho a agosto');
A6: Prunus domestica | B6: Ameixoeira | C6: BLACK BEAUTY | D6: Permanente | F6: Novembro a dezembro | G6: Fevereiro a março | H6: Julho a agosto | J6: =1+J5 -> 5 | K6: Daucus carota subsp. Sativus | L6: Cenoura | M6: 2 | S6: {=_xlfn.XLOOKUP(A6&B6,$K$2:$K$13&$L$2:$L$13,$J$2:$J$13)} -> 1 | T6: BLACK BEAUTY | U6: 5 | V6: =_xlfn.CONCAT(B6," ",C6) -> Ameixoeira BLACK BEAUTY | W6: ="INSERT INTO Cultura(CulturaID, Variedade, EspecieVegetalID, EpocaSementeiraPlantacao, EpocaPoda, EpocaFloracao, EpocaColheita) VALUES ("&U6&", '"&T6&"', "&S6&", '"&E6&"', '"&F6&"', '"&G6&"', '"&H6&"');" -> INSERT INTO Cultura(CulturaID, Variedade, EspecieVegetalID, EpocaSementeiraPlantacao, EpocaPoda, EpocaFloracao, EpocaColheita) VALUES (5, 'BLACK BEAUTY', 1, '', 'Novembro a dezembro', 'Fevereiro a março', 'Julho a agosto');
A7: Prunus domestica | B7: Ameixoeira | C7: BLACK STAR | D7: Permanente | F7: Novembro a dezembro | G7: Fevereiro a março | H7: Julho a agosto | J7: =1+J6 -> 6 | K7: Lupinus luteus | L7: Tremoço | M7: 2 | S7: {=_xlfn.XLOOKUP(A7&B7,$K$2:$K$13&$L$2:$L$13,$J$2:$J$13)} -> 1 | T7: BLACK STAR | U7: 6 | V7: =_xlfn.CONCAT(B7," ",C7) -> Ameixoeira BLACK STAR | W7: ="INSERT INTO Cultura(CulturaID, Variedade, EspecieVegetalID, EpocaSementeiraPlantacao, EpocaPoda, EpocaFloracao, EpocaColheita) VALUES ("&U7&", '"&T7&"', "&S7&", '"&E7&"', '"&F7&"', '"&G7&"', '"&H7&"');" -> INSERT INTO Cultura(CulturaID, Variedade, EspecieVegetalID, EpocaSementeiraPlantacao, EpocaPoda, EpocaFloracao, EpocaColheita) VALUES (6, 'BLACK STAR', 1, '', 'Novembro a dezembro', 'Fevereiro a março', 'Julho a agosto');
A8: Prunus domestica | B8: Ameixoeira | C8: BLACK GOLD | D8: Permanente | F8: Novembro a dezembro | G8: Fevereiro a março | H8: Julho a agosto | J8: =1+J7 -> 7 | K8: Lupinus albus | L8: Tremoço | M8: 2 | S8: {=_xlfn.XLOOKUP(A8&B8,$K$2:$K$13&$L$2:$L$13,$J$2:$J$13)} -> 1 | T8: BLACK GOLD | U8: 7 | V8: =_xlfn.CONCAT(B8," ",C8) -> Ameixoeira BLACK GOLD | W8: ="INSERT INTO Cultura(CulturaID, Variedade, EspecieVegetalID, EpocaSementeiraPlantacao, EpocaPoda, EpocaFloracao, EpocaColheita) VALUES ("&U8&", '"&T8&"', "&S8&", '"&E8&"', '"&F8&"', '"&G8&"', '"&H8&"');" -> INSERT INTO Cultura(CulturaID, Variedade, EspecieVegetalID, EpocaSementeiraPlantacao, EpocaPoda, EpocaFloracao, EpocaColheita) VALUES (7, 'BLACK GOLD', 1, '', 'Novembro a dezembro', 'Fevereiro a março', 'Julho a agosto');
A9: Prunus domestica | B9: Ameixoeira | C9: BLACK DIAMOND | D9: Permanente | F9: Novembro a dezembro | G9: Fevereiro a março | H9: Julho a agosto | J9: =1+J8 -> 8 | K9: Zea mays | L9: Milho | M9: 2 | S9: {=_xlfn.XLOOKUP(A9&B9,$K$2:$K$13&$L$2:$L$13,$J$2:$J$13)} -> 1 | T9: BLACK DIAMOND | U9: 8 | V9: =_xlfn.CONCAT(B9," ",C9) -> Ameixoeira BLACK DIAMOND | W9: ="INSERT INTO Cultura(CulturaID, Variedade, EspecieVegetalID, EpocaSementeiraPlantacao, EpocaPoda, EpocaFloracao, EpocaColheita) VALUES ("&U9&", '"&T9&"', "&S9&", '"&E9&"', '"&F9&"', '"&G9&"', '"&H9&"');" -> INSERT INTO Cultura(CulturaID, Variedade, EspecieVegetalID, EpocaSementeiraPlantacao, EpocaPoda, EpocaFloracao, EpocaColheita) VALUES (8, 'BLACK DIAMOND', 1, '', 'Novembro a dezembro', 'Fevereiro a março', 'Julho a agosto');
A10: Prunus domestica | B10: Ameixoeira | C10: BLACK AMBER | D10: Permanente | F10: Novembro a dezembro | G10: Fevereiro a março | H10: Julho a agosto | J10: =1+J9 -> 9 | K10: Brassica rapa | L10: Nabo greleiro | M10: 2 | S10: {=_xlfn.XLOOKUP(A10&B10,$K$2:$K$13&$L$2:$L$13,$J$2:$J$13)} -> 1 | T10: BLACK AMBER | U10: 9 | V10: =_xlfn.CONCAT(B10," ",C10) -> Ameixoeira BLACK AMBER | W10: ="INSERT INTO Cultura(CulturaID, Variedade, EspecieVegetalID, EpocaSementeiraPlantacao, EpocaPoda, EpocaFloracao, EpocaColheita) VALUES ("&U10&", '"&T10&"', "&S10&", '"&E10&"', '"&F10&"', '"&G10&"', '"&H10&"');" -> INSERT INTO Cultura(CulturaID, Variedade, EspecieVegetalID, EpocaSementeiraPlantacao, EpocaPoda, EpocaFloracao, EpocaColheita) VALUES (9, 'BLACK AMBER', 1, '', 'Novembro a dezembro', 'Fevereiro a março', 'Julho a agosto');
A11: Prunus domestica | B11: Ameixoeira | C11: BLACK SPLENDOR | D11: Permanente | F11: Novembro a dezembro | G11: Fevereiro a março | H11: Julho a agosto | J11: =1+J10 -> 10 | K11: Olea europaea | L11: Oliveira | M11: 1 | S11: {=_xlfn.XLOOKUP(A11&B11,$K$2:$K$13&$L$2:$L$13,$J$2:$J$13)} -> 1 | T11: BLACK SPLENDOR | U11: 10 | V11: =_xlfn.CONCAT(B11," ",C11) -> Ameixoeira BLACK SPLENDOR | W11: ="INSERT INTO Cultura(CulturaID, Variedade, EspecieVegetalID, EpocaSementeiraPlantacao, EpocaPoda, EpocaFloracao, EpocaColheita) VALUES ("&U11&", '"&T11&"', "&S11&", '"&E11&"', '"&F11&"', '"&G11&"', '"&H11&"');" -> INSERT INTO Cultura(CulturaID, Variedade, EspecieVegetalID, EpocaSementeiraPlantacao, EpocaPoda, EpocaFloracao, EpocaColheita) VALUES (10, 'BLACK SPLENDOR', 1, '', 'Novembro a dezembro', 'Fevereiro a março', 'Julho a agosto');
A12: Prunus domestica | B12: Ameixoeira | C12: FORTUNA | D12: Permanente | F12: Novembro a dezembro | G12: Fevereiro a março | H12: Julho a agosto | J12: =1+J11 -> 11 | K12: Brassica rapa | L12: Nabo | M12: 2 | S12: {=_xlfn.XLOOKUP(A12&B12,$K$2:$K$13&$L$2:$L$13,$J$2:$J$13)} -> 1 | T12: FORTUNA | U12: 11 | V12: =_xlfn.CONCAT(B12," ",C12) -> Ameixoeira FORTUNA | W12: ="INSERT INTO Cultura(CulturaID, Variedade, EspecieVegetalID, EpocaSementeiraPlantacao, EpocaPoda, EpocaFloracao, EpocaColheita) VALUES ("&U12&", '"&T12&"', "&S12&", '"&E12&"', '"&F12&"', '"&G12&"', '"&H12&"');" -> INSERT INTO Cultura(CulturaID, Variedade, EspecieVegetalID, EpocaSementeiraPlantacao, EpocaPoda, EpocaFloracao, EpocaColheita) VALUES (11, 'FORTUNA', 1, '', 'Novembro a dezembro', 'Fevereiro a março', 'Julho a agosto');
A13: Prunus domestica | B13: Ameixoeira | C13: FRIAR | D13: Permanente | F13: Novembro a dezembro | G13: Fevereiro a março | H13: Julho a agosto | J13: =1+J12 -> 12 | K13: Vitis vinifera | L13: Videira | M13: =IF(K13=A96,J31,0) -> 1 | S13: {=_xlfn.XLOOKUP(A13&B13,$K$2:$K$13&$L$2:$L$13,$J$2:$J$13)} -> 1 | T13: FRIAR | U13: 12 | V13: =_xlfn.CONCAT(B13," ",C13) -> Ameixoeira FRIAR | W13: ="INSERT INTO Cultura(CulturaID, Variedade, EspecieVegetalID, EpocaSementeiraPlantacao, EpocaPoda, EpocaFloracao, EpocaColheita) VALUES ("&U13&", '"&T13&"', "&S13&", '"&E13&"', '"&F13&"', '"&G13&"', '"&H13&"');" -> INSERT INTO Cultura(CulturaID, Variedade, EspecieVegetalID, EpocaSementeiraPlantacao, EpocaPoda, EpocaFloracao, EpocaColheita) VALUES (12, 'FRIAR', 1, '', 'Novembro a dezembro', 'Fevereiro a março', 'Julho a agosto');
A14: Prunus domestica | B14: Ameixoeira | C14: EL DORADO | D14: Permanente | F14: Novembro a dezembro | G14: Fevereiro a março | H14: Julho a agosto | J14: Tabela EspecieVegetal | S14: {=_xlfn.XLOOKUP(A14&B14,$K$2:$K$13&$L$2:$L$13,$J$2:$J$13)} -> 1 | T14: EL DORADO | U14: 13 | V14: =_xlfn.CONCAT(B14," ",C14) -> Ameixoeira EL DORADO | W14: ="INSERT INTO Cultura(CulturaID, Variedade, EspecieVegetalID, EpocaSementeiraPlantacao, EpocaPoda, EpocaFloracao, EpocaColheita) VALUES ("&U14&", '"&T14&"', "&S14&", '"&E14&"', '"&F14&"', '"&G14&"', '"&H14&"');" -> INSERT INTO Cultura(CulturaID, Variedade, EspecieVegetalID, EpocaSementeiraPlantacao, EpocaPoda, EpocaFloracao, EpocaColheita) VALUES (13, 'EL DORADO', 1, '', 'Novembro a dezembro', 'Fevereiro a março', 'Julho a agosto');
A15: Prunus domestica | B15: Ameixoeira | C15: ELEPHANT HEART | D15: Permanente | F15: Novembro a dezembro | G15: Fevereiro a março | H15: Julho a agosto | J15: ="INSERT INTO EspecieVegetal (EspecieVegetalID, DesignacaoEspecie, NomeComum, TipoCulturaID) VALUES ("&J2&", '"&K2&"', '"&L2&"', "&M2&");" -> INSERT INTO EspecieVegetal (EspecieVegetalID, DesignacaoEspecie, NomeComum, TipoCulturaID) VALUES (1, 'Prunus domestica', 'Ameixoeira', 1); | R15: 2 | S15: {=_xlfn.XLOOKUP(A15&B15,$K$2:$K$13&$L$2:$L$13,$J$2:$J$13)} -> 1 | T15: ELEPHANT HEART | U15: 14 | V15: =_xlfn.CONCAT(B15," ",C15) -> Ameixoeira ELEPHANT HEART | W15: ="INSERT INTO Cultura(CulturaID, Variedade, EspecieVegetalID, EpocaSementeiraPlantacao, EpocaPoda, EpocaFloracao, EpocaColheita) VALUES ("&U15&", '"&T15&"', "&S15&", '"&E15&"', '"&F15&"', '"&G15&"', '"&H15&"');" -> INSERT INTO Cultura(CulturaID, Variedade, EspecieVegetalID, EpocaSementeiraPlantacao, EpocaPoda, EpocaFloracao, EpocaColheita) VALUES (14, 'ELEPHANT HEART', 1, '', 'Novembro a dezembro', 'Fevereiro a março', 'Julho a agosto');
A16: Prunus domestica | B16: Ameixoeira | C16: GOLDEN JAPAN | D16: Permanente | F16: Novembro a dezembro | G16: Fevereiro a março | H16: Julho a agosto | J16: ="INSERT INTO EspecieVegetal (EspecieVegetalID, DesignacaoEspecie, NomeComum, TipoCulturaID) VALUES ("&J3&", '"&K3&"', '"&L3&"', "&M3&");" -> INSERT INTO EspecieVegetal (EspecieVegetalID, DesignacaoEspecie, NomeComum, TipoCulturaID) VALUES (2, 'Prunus armeniaca', 'Damasqueiro', 1); | S16: {=_xlfn.XLOOKUP(A16&B16,$K$2:$K$13&$L$2:$L$13,$J$2:$J$13)} -> 1 | T16: GOLDEN JAPAN | U16: 15 | V16: =_xlfn.CONCAT(B16," ",C16) -> Ameixoeira GOLDEN JAPAN | W16: ="INSERT INTO Cultura(CulturaID, Variedade, EspecieVegetalID, EpocaSementeiraPlantacao, EpocaPoda, EpocaFloracao, EpocaColheita) VALUES ("&U16&", '"&T16&"', "&S16&", '"&E16&"', '"&F16&"', '"&G16&"', '"&H16&"');" -> INSERT INTO Cultura(CulturaID, Variedade, EspecieVegetalID, EpocaSementeiraPlantacao, EpocaPoda, EpocaFloracao, EpocaColheita) VALUES (15, 'GOLDEN JAPAN', 1, '', 'Novembro a dezembro', 'Fevereiro a março', 'Julho a agosto');
A17: Prunus domestica | B17: Ameixoeira | C17: HARRY PITCHON | D17: Permanente | F17: Novembro a dezembro | G17: Fevereiro a março | H17: Julho a agosto | J17: ="INSERT INTO EspecieVegetal (EspecieVegetalID, DesignacaoEspecie, NomeComum, TipoCulturaID) VALUES ("&J4&", '"&K4&"', '"&L4&"', "&M4&");" -> INSERT INTO EspecieVegetal (EspecieVegetalID, DesignacaoEspecie, NomeComum, TipoCulturaID) VALUES (3, 'Malus domestica', 'Macieira', 1); | S17: {=_xlfn.XLOOKUP(A17&B17,$K$2:$K$13&$L$2:$L$13,$J$2:$J$13)} -> 1 | T17: HARRY PITCHON | U17: 16 | V17: =_xlfn.CONCAT(B17," ",C17) -> Ameixoeira HARRY PITCHON | W17: ="INSERT INTO Cultura(CulturaID, Variedade, EspecieVegetalID, EpocaSementeiraPlantacao, EpocaPoda, EpocaFloracao, EpocaColheita) VALUES ("&U17&", '"&T17&"', "&S17&", '"&E17&"', '"&F17&"', '"&G17&"', '"&H17&"');" -> INSERT INTO Cultura(CulturaID, Variedade, EspecieVegetalID, EpocaSementeiraPlantacao, EpocaPoda, EpocaFloracao, EpocaColheita) VALUES (16, 'HARRY PITCHON', 1, '', 'Novembro a dezembro', 'Fevereiro a março', 'Julho a agosto');
A18: Prunus domestica | B18: Ameixoeira | C18: LAETITIA | D18: Permanente | F18: Novembro a dezembro | G18: Fevereiro a março | H18: Julho a agosto | J18: ="INSERT INTO EspecieVegetal (EspecieVegetalID, DesignacaoEspecie, NomeComum, TipoCulturaID) VALUES ("&J5&", '"&K5&"', '"&L5&"', "&M5&");" -> INSERT INTO EspecieVegetal (EspecieVegetalID, DesignacaoEspecie, NomeComum, TipoCulturaID) VALUES (4, 'Pyrus pyrifolia', 'Pera Nashi', 1); | S18: {=_xlfn.XLOOKUP(A18&B18,$K$2:$K$13&$L$2:$L$13,$J$2:$J$13)} -> 1 | T18: LAETITIA | U18: 17 | V18: =_xlfn.CONCAT(B18," ",C18) -> Ameixoeira LAETITIA | W18: ="INSERT INTO Cultura(CulturaID, Variedade, EspecieVegetalID, EpocaSementeiraPlantacao, EpocaPoda, EpocaFloracao, EpocaColheita) VALUES ("&U18&", '"&T18&"', "&S18&", '"&E18&"', '"&F18&"', '"&G18&"', '"&H18&"');" -> INSERT INTO Cultura(CulturaID, Variedade, EspecieVegetalID, EpocaSementeiraPlantacao, EpocaPoda, EpocaFloracao, EpocaColheita) VALUES (17, 'LAETITIA', 1, '', 'Novembro a dezembro', 'Fevereiro a março', 'Julho a agosto');
A19: Prunus domestica | B19: Ameixoeira | C19: METLEY | D19: Permanente | F19: Novembro a dezembro | G19: Fevereiro a março | H19: Julho a agosto | J19: ="INSERT INTO EspecieVegetal (EspecieVegetalID, DesignacaoEspecie, NomeComum, TipoCulturaID) VALUES ("&J6&", '"&K6&"', '"&L6&"', "&M6&");" -> INSERT INTO EspecieVegetal (EspecieVegetalID, DesignacaoEspecie, NomeComum, TipoCulturaID) VALUES (5, 'Daucus carota subsp. Sativus', 'Cenoura', 2); | S19: {=_xlfn.XLOOKUP(A19&B19,$K$2:$K$13&$L$2:$L$13,$J$2:$J$13)} -> 1 | T19: METLEY | U19: 18 | V19: =_xlfn.CONCAT(B19," ",C19) -> Ameixoeira METLEY | W19: ="INSERT INTO Cultura(CulturaID, Variedade, EspecieVegetalID, EpocaSementeiraPlantacao, EpocaPoda, EpocaFloracao, EpocaColheita) VALUES ("&U19&", '"&T19&"', "&S19&", '"&E19&"', '"&F19&"', '"&G19&"', '"&H19&"');" -> INSERT INTO Cultura(CulturaID, Variedade, EspecieVegetalID, EpocaSementeiraPlantacao, EpocaPoda, EpocaFloracao, EpocaColheita) VALUES (18, 'METLEY', 1, '', 'Novembro a dezembro', 'Fevereiro a março', 'Julho a agosto');
A20: Prunus domestica | B20: Ameixoeira | C20: MIRABELLE DE NANCY | D20: Permanente | F20: Novembro a dezembro | G20: Fevereiro a março | H20: Julho a agosto | J20: ="INSERT INTO EspecieVegetal (EspecieVegetalID, DesignacaoEspecie, NomeComum, TipoCulturaID) VALUES ("&J7&", '"&K7&"', '"&L7&"', "&M7&");" -> INSERT INTO EspecieVegetal (EspecieVegetalID, DesignacaoEspecie, NomeComum, TipoCulturaID) VALUES (6, 'Lupinus luteus', 'Tremoço', 2); | S20: {=_xlfn.XLOOKUP(A20&B20,$K$2:$K$13&$L$2:$L$13,$J$2:$J$13)} -> 1 | T20: MIRABELLE DE NANCY | U20: 19 | V20: =_xlfn.CONCAT(B20," ",C20) -> Ameixoeira MIRABELLE DE NANCY | W20: ="INSERT INTO Cultura(CulturaID, Variedade, EspecieVegetalID, EpocaSementeiraPlantacao, EpocaPoda, EpocaFloracao, EpocaColheita) VALUES ("&U20&", '"&T20&"', "&S20&", '"&E20&"', '"&F20&"', '"&G20&"', '"&H20&"');" -> INSERT INTO Cultura(CulturaID, Variedade, EspecieVegetalID, EpocaSementeiraPlantacao, EpocaPoda, EpocaFloracao, EpocaColheita) VALUES (19, 'MIRABELLE DE NANCY', 1, '', 'Novembro a dezembro', 'Fevereiro a março', 'Julho a agosto');
A21: Prunus domestica | B21: Ameixoeira | C21: QUEEN ROSE | D21: Permanente | F21: Novembro a dezembro | G21: Fevereiro a março | H21: Julho a agosto | J21: ="INSERT INTO EspecieVegetal (EspecieVegetalID, DesignacaoEspecie, NomeComum, TipoCulturaID) VALUES ("&J8&", '"&K8&"', '"&L8&"', "&M8&");" -> INSERT INTO EspecieVegetal (EspecieVegetalID, DesignacaoEspecie, NomeComum, TipoCulturaID) VALUES (7, 'Lupinus albus', 'Tremoço', 2); | S21: {=_xlfn.XLOOKUP(A21&B21,$K$2:$K$13&$L$2:$L$13,$J$2:$J$13)} -> 1 | T21: QUEEN ROSE | U21: 20 | V21: =_xlfn.CONCAT(B21," ",C21) -> Ameixoeira QUEEN ROSE | W21: ="INSERT INTO Cultura(CulturaID, Variedade, EspecieVegetalID, EpocaSementeiraPlantacao, EpocaPoda, EpocaFloracao, EpocaColheita) VALUES ("&U21&", '"&T21&"', "&S21&", '"&E21&"', '"&F21&"', '"&G21&"', '"&H21&"');" -> INSERT INTO Cultura(CulturaID, Variedade, EspecieVegetalID, EpocaSementeiraPlantacao, EpocaPoda, EpocaFloracao, EpocaColheita) VALUES (20, 'QUEEN ROSE', 1, '', 'Novembro a dezembro', 'Fevereiro a março', 'Julho a agosto');
A22: Prunus domestica | B22: Ameixoeira | C22: RED BEAUT | D22: Permanente | F22: Novembro a dezembro | G22: Fevereiro a março | H22: Julho a agosto | J22: ="INSERT INTO EspecieVegetal (EspecieVegetalID, DesignacaoEspecie, NomeComum, TipoCulturaID) VALUES ("&J9&", '"&K9&"', '"&L9&"', "&M9&");" -> INSERT INTO EspecieVegetal (EspecieVegetalID, DesignacaoEspecie, NomeComum, TipoCulturaID) VALUES (8, 'Zea mays', 'Milho', 2); | S22: {=_xlfn.XLOOKUP(A22&B22,$K$2:$K$13&$L$2:$L$13,$J$2:$J$13)} -> 1 | T22: RED BEAUT | U22: 21 | V22: =_xlfn.CONCAT(B22," ",C22) -> Ameixoeira RED BEAUT | W22: ="INSERT INTO Cultura(CulturaID, Variedade, EspecieVegetalID, EpocaSementeiraPlantacao, EpocaPoda, EpocaFloracao, EpocaColheita) VALUES ("&U22&", '"&T22&"', "&S22&", '"&E22&"', '"&F22&"', '"&G22&"', '"&H22&"');" -> INSERT INTO Cultura(CulturaID, Variedade, EspecieVegetalID, EpocaSementeiraPlantacao, EpocaPoda, EpocaFloracao, EpocaColheita) VALUES (21, 'RED BEAUT', 1, '', 'Novembro a dezembro', 'Fevereiro a março', 'Julho a agosto');
A23: Prunus domestica | B23: Ameixoeira | C23: SANTA ROSA | D23: Permanente | F23: Novembro a dezembro | G23: Fevereiro a março | H23: Julho a agosto | J23: ="INSERT INTO EspecieVegetal (EspecieVegetalID, DesignacaoEspecie, NomeComum, TipoCulturaID) VALUES ("&J10&", '"&K10&"', '"&L10&"', "&M10&");" -> INSERT INTO EspecieVegetal (EspecieVegetalID, DesignacaoEspecie, NomeComum, TipoCulturaID) VALUES (9, 'Brassica rapa', 'Nabo greleiro', 2); | S23: {=_xlfn.XLOOKUP(A23&B23,$K$2:$K$13&$L$2:$L$13,$J$2:$J$13)} -> 1 | T23: SANTA ROSA | U23: 22 | V23: =_xlfn.CONCAT(B23," ",C23) -> Ameixoeira SANTA ROSA | W23: ="INSERT INTO Cultura(CulturaID, Variedade, EspecieVegetalID, EpocaSementeiraPlantacao, EpocaPoda, EpocaFloracao, EpocaColheita) VALUES ("&U23&", '"&T23&"', "&S23&", '"&E23&"', '"&F23&"', '"&G23&"', '"&H23&"');" -> INSERT INTO Cultura(CulturaID, Variedade, EspecieVegetalID, EpocaSementeiraPlantacao, EpocaPoda, EpocaFloracao, EpocaColheita) VALUES (22, 'SANTA ROSA', 1, '', 'Novembro a dezembro', 'Fevereiro a março', 'Julho a agosto');
A24: Prunus domestica | B24: Ameixoeira | C24: SHIRO | D24: Permanente | F24: Novembro a dezembro | G24: Fevereiro a março | H24: Julho a agosto | J24: ="INSERT INTO EspecieVegetal (EspecieVegetalID, DesignacaoEspecie, NomeComum, TipoCulturaID) VALUES ("&J11&", '"&K11&"', '"&L11&"', "&M11&");" -> INSERT INTO EspecieVegetal (EspecieVegetalID, DesignacaoEspecie, NomeComum, TipoCulturaID) VALUES (10, 'Olea europaea', 'Oliveira', 1); | S24: {=_xlfn.XLOOKUP(A24&B24,$K$2:$K$13&$L$2:$L$13,$J$2:$J$13)} -> 1 | T24: SHIRO | U24: 23 | V24: =_xlfn.CONCAT(B24," ",C24) -> Ameixoeira SHIRO | W24: ="INSERT INTO Cultura(CulturaID, Variedade, EspecieVegetalID, EpocaSementeiraPlantacao, EpocaPoda, EpocaFloracao, EpocaColheita) VALUES ("&U24&", '"&T24&"', "&S24&", '"&E24&"', '"&F24&"', '"&G24&"', '"&H24&"');" -> INSERT INTO Cultura(CulturaID, Variedade, EspecieVegetalID, EpocaSementeiraPlantacao, EpocaPoda, EpocaFloracao, EpocaColheita) VALUES (23, 'SHIRO', 1, '', 'Novembro a dezembro', 'Fevereiro a março', 'Julho a agosto');
A25: Prunus domestica | B25: Ameixoeira | C25: SUNGOLD | D25: Permanente | F25: Novembro a dezembro | G25: Fevereiro a março | H25: Julho a agosto | J25: ="INSERT INTO EspecieVegetal (EspecieVegetalID, DesignacaoEspecie, NomeComum, TipoCulturaID) VALUES ("&J12&", '"&K12&"', '"&L12&"', "&M12&");" -> INSERT INTO EspecieVegetal (EspecieVegetalID, DesignacaoEspecie, NomeComum, TipoCulturaID) VALUES (11, 'Brassica rapa', 'Nabo', 2); | S25: {=_xlfn.XLOOKUP(A25&B25,$K$2:$K$13&$L$2:$L$13,$J$2:$J$13)} -> 1 | T25: SUNGOLD | U25: 24 | V25: =_xlfn.CONCAT(B25," ",C25) -> Ameixoeira SUNGOLD | W25: ="INSERT INTO Cultura(CulturaID, Variedade, EspecieVegetalID, EpocaSementeiraPlantacao, EpocaPoda, EpocaFloracao, EpocaColheita) VALUES ("&U25&", '"&T25&"', "&S25&", '"&E25&"', '"&F25&"', '"&G25&"', '"&H25&"');" -> INSERT INTO Cultura(CulturaID, Variedade, EspecieVegetalID, EpocaSementeiraPlantacao, EpocaPoda, EpocaFloracao, EpocaColheita) VALUES (24, 'SUNGOLD', 1, '', 'Novembro a dezembro', 'Fevereiro a março', 'Julho a agosto');
A26: Prunus domestica | B26: Ameixoeira | C26: WILSON PERFECTION | D26: Permanente | F26: Novembro a dezembro | G26: Fevereiro a março | H26: Julho a agosto | J26: ="INSERT INTO EspecieVegetal (EspecieVegetalID, DesignacaoEspecie, NomeComum, TipoCulturaID) VALUES ("&J13&", '"&K13&"', '"&L13&"', "&M13&");" -> INSERT INTO EspecieVegetal (EspecieVegetalID, DesignacaoEspecie, NomeComum, TipoCulturaID) VALUES (12, 'Vitis vinifera', 'Videira', 1); | S26: {=_xlfn.XLOOKUP(A26&B26,$K$2:$K$13&$L$2:$L$13,$J$2:$J$13)} -> 1 | T26: WILSON PERFECTION | U26: 25 | V26: =_xlfn.CONCAT(B26," ",C26) -> Ameixoeira WILSON PERFECTION | W26: ="INSERT INTO Cultura(CulturaID, Variedade, EspecieVegetalID, EpocaSementeiraPlantacao, EpocaPoda, EpocaFloracao, EpocaColheita) VALUES ("&U26&", '"&T26&"', "&S26&", '"&E26&"', '"&F26&"', '"&G26&"', '"&H26&"');" -> INSERT INTO Cultura(CulturaID, Variedade, EspecieVegetalID, EpocaSementeiraPlantacao, EpocaPoda, EpocaFloracao, EpocaColheita) VALUES (25, 'WILSON PERFECTION', 1, '', 'Novembro a dezembro', 'Fevereiro a março', 'Julho a agosto');
A27: Prunus domestica | B27: Ameixoeira | C27: AUTUMN GIANT | D27: Permanente | F27: Novembro a dezembro | G27: Fevereiro a março | H27: Julho a agosto | S27: {=_xlfn.XLOOKUP(A27&B27,$K$2:$K$13&$L$2:$L$13,$J$2:$J$13)} -> 1 | T27: AUTUMN GIANT | U27: 26 | V27: =_xlfn.CONCAT(B27," ",C27) -> Ameixoeira AUTUMN GIANT | W27: ="INSERT INTO Cultura(CulturaID, Variedade, EspecieVegetalID, EpocaSementeiraPlantacao, EpocaPoda, EpocaFloracao, EpocaColheita) VALUES ("&U27&", '"&T27&"', "&S27&", '"&E27&"', '"&F27&"', '"&G27&"', '"&H27&"');" -> INSERT INTO Cultura(CulturaID, Variedade, EspecieVegetalID, EpocaSementeiraPlantacao, EpocaPoda, EpocaFloracao, EpocaColheita) VALUES (26, 'AUTUMN GIANT', 1, '', 'Novembro a dezembro', 'Fevereiro a março', 'Julho a agosto');
A28: Prunus armeniaca | B28: Damasqueiro | C28: BULIDA | D28: Permanente | F28: Novembro a dezembro | G28: Fevereiro a março | H28: Julho a agosto | S28: {=_xlfn.XLOOKUP(A28&B28,$K$2:$K$13&$L$2:$L$13,$J$2:$J$13)} -> 2 | T28: BULIDA | U28: 27 | V28: =_xlfn.CONCAT(B28," ",C28) -> Damasqueiro BULIDA | W28: ="INSERT INTO Cultura(CulturaID, Variedade, EspecieVegetalID, EpocaSementeiraPlantacao, EpocaPoda, EpocaFloracao, EpocaColheita) VALUES ("&U28&", '"&T28&"', "&S28&", '"&E28&"', '"&F28&"', '"&G28&"', '"&H28&"');" -> INSERT INTO Cultura(CulturaID, Variedade, EspecieVegetalID, EpocaSementeiraPlantacao, EpocaPoda, EpocaFloracao, EpocaColheita) VALUES (27, 'BULIDA', 2, '', 'Novembro a dezembro', 'Fevereiro a março', 'Julho a agosto');
A29: Prunus armeniaca | B29: Damasqueiro | C29: CANINO | D29: Permanente | F29: Novembro a dezembro | G29: Fevereiro a março | H29: Julho a agosto | J29: TipoCultura | S29: {=_xlfn.XLOOKUP(A29&B29,$K$2:$K$13&$L$2:$L$13,$J$2:$J$13)} -> 2 | T29: CANINO | U29: 28 | V29: =_xlfn.CONCAT(B29," ",C29) -> Damasqueiro CANINO | W29: ="INSERT INTO Cultura(CulturaID, Variedade, EspecieVegetalID, EpocaSementeiraPlantacao, EpocaPoda, EpocaFloracao, EpocaColheita) VALUES ("&U29&", '"&T29&"', "&S29&", '"&E29&"', '"&F29&"', '"&G29&"', '"&H29&"');" -> INSERT INTO Cultura(CulturaID, Variedade, EspecieVegetalID, EpocaSementeiraPlantacao, EpocaPoda, EpocaFloracao, EpocaColheita) VALUES (28, 'CANINO', 2, '', 'Novembro a dezembro', 'Fevereiro a março', 'Julho a agosto');
A30: Prunus armeniaca | B30: Damasqueiro | C30: LIABAUD | D30: Permanente | F30: Novembro a dezembro | G30: Fevereiro a março | H30: Julho a agosto | J30: TipoCulturaID | K30: DesignaçãoTipoCultura | S30: {=_xlfn.XLOOKUP(A30&B30,$K$2:$K$13&$L$2:$L$13,$J$2:$J$13)} -> 2 | T30: LIABAUD | U30: 29 | V30: =_xlfn.CONCAT(B30," ",C30) -> Damasqueiro LIABAUD | W30: ="INSERT INTO Cultura(CulturaID, Variedade, EspecieVegetalID, EpocaSementeiraPlantacao, EpocaPoda, EpocaFloracao, EpocaColheita) VALUES ("&U30&", '"&T30&"', "&S30&", '"&E30&"', '"&F30&"', '"&G30&"', '"&H30&"');" -> INSERT INTO Cultura(CulturaID, Variedade, EspecieVegetalID, EpocaSementeiraPlantacao, EpocaPoda, EpocaFloracao, EpocaColheita) VALUES (29, 'LIABAUD', 2, '', 'Novembro a dezembro', 'Fevereiro a março', 'Julho a agosto');
A31: Prunus armeniaca | B31: Damasqueiro | C31: MAILLOT JAUNE | D31: Permanente | F31: Novembro a dezembro | G31: Fevereiro a março | H31: Julho a agosto | J31: 1 | K31: {=_xlfn.UNIQUE(D2:D96)} -> Permanente | S31: {=_xlfn.XLOOKUP(A31&B31,$K$2:$K$13&$L$2:$L$13,$J$2:$J$13)} -> 2 | T31: MAILLOT JAUNE | U31: 30 | V31: =_xlfn.CONCAT(B31," ",C31) -> Damasqueiro MAILLOT JAUNE | W31: ="INSERT INTO Cultura(CulturaID, Variedade, EspecieVegetalID, EpocaSementeiraPlantacao, EpocaPoda, EpocaFloracao, EpocaColheita) VALUES ("&U31&", '"&T31&"', "&S31&", '"&E31&"', '"&F31&"', '"&G31&"', '"&H31&"');" -> INSERT INTO Cultura(CulturaID, Variedade, EspecieVegetalID, EpocaSementeiraPlantacao, EpocaPoda, EpocaFloracao, EpocaColheita) VALUES (30, 'MAILLOT JAUNE', 2, '', 'Novembro a dezembro', 'Fevereiro a março', 'Julho a agosto');
A32: Prunus armeniaca | B32: Damasqueiro | C32: POLONAIS | D32: Permanente | F32: Novembro a dezembro | G32: Fevereiro a março | H32: Julho a agosto | J32: 2 | K32: Temporária | S32: {=_xlfn.XLOOKUP(A32&B32,$K$2:$K$13&$L$2:$L$13,$J$2:$J$13)} -> 2 | T32: POLONAIS | U32: 31 | V32: =_xlfn.CONCAT(B32," ",C32) -> Damasqueiro POLONAIS | W32: ="INSERT INTO Cultura(CulturaID, Variedade, EspecieVegetalID, EpocaSementeiraPlantacao, EpocaPoda, EpocaFloracao, EpocaColheita) VALUES ("&U32&", '"&T32&"', "&S32&", '"&E32&"', '"&F32&"', '"&G32&"', '"&H32&"');" -> INSERT INTO Cultura(CulturaID, Variedade, EspecieVegetalID, EpocaSementeiraPlantacao, EpocaPoda, EpocaFloracao, EpocaColheita) VALUES (31, 'POLONAIS', 2, '', 'Novembro a dezembro', 'Fevereiro a março', 'Julho a agosto');
A33: Malus domestica | B33: Macieira | C33: AKANE | D33: Permanente | F33: Novembro a dezembro | G33: Março a abril | H33: Agosto a setembro | J33: ="INSERT INTO TipoCultura(TipoCulturaID, DesignacaoTipoCultura) VALUES ("&J31&", '"&K31&"');" -> INSERT INTO TipoCultura(TipoCulturaID, DesignacaoTipoCultura) VALUES (1, 'Permanente'); | P33: 1 | S33: {=_xlfn.XLOOKUP(A33&B33,$K$2:$K$13&$L$2:$L$13,$J$2:$J$13)} -> 3 | T33: AKANE | U33: 32 | V33: =_xlfn.CONCAT(B33," ",C33) -> Macieira AKANE | W33: ="INSERT INTO Cultura(CulturaID, Variedade, EspecieVegetalID, EpocaSementeiraPlantacao, EpocaPoda, EpocaFloracao, EpocaColheita) VALUES ("&U33&", '"&T33&"', "&S33&", '"&E33&"', '"&F33&"', '"&G33&"', '"&H33&"');" -> INSERT INTO Cultura(CulturaID, Variedade, EspecieVegetalID, EpocaSementeiraPlantacao, EpocaPoda, EpocaFloracao, EpocaColheita) VALUES (32, 'AKANE', 3, '', 'Novembro a dezembro', 'Março a abril', 'Agosto a setembro');
A34: Malus domestica | B34: Macieira | C34: BELGOLDEN | D34: Permanente | F34: Novembro a dezembro | G34: Março a abril | H34: Agosto a setembro | J34: ="INSERT INTO TipoCultura(TipoCulturaID, DesignacaoTipoCultura) VALUES ("&J32&", '"&K32&"');" -> INSERT INTO TipoCultura(TipoCulturaID, DesignacaoTipoCultura) VALUES (2, 'Temporária'); | S34: {=_xlfn.XLOOKUP(A34&B34,$K$2:$K$13&$L$2:$L$13,$J$2:$J$13)} -> 3 | T34: BELGOLDEN | U34: 33 | V34: =_xlfn.CONCAT(B34," ",C34) -> Macieira BELGOLDEN | W34: ="INSERT INTO Cultura(CulturaID, Variedade, EspecieVegetalID, EpocaSementeiraPlantacao, EpocaPoda, EpocaFloracao, EpocaColheita) VALUES ("&U34&", '"&T34&"', "&S34&", '"&E34&"', '"&F34&"', '"&G34&"', '"&H34&"');" -> INSERT INTO Cultura(CulturaID, Variedade, EspecieVegetalID, EpocaSementeiraPlantacao, EpocaPoda, EpocaFloracao, EpocaColheita) VALUES (33, 'BELGOLDEN', 3, '', 'Novembro a dezembro', 'Março a abril', 'Agosto a setembro');
A35: Malus domestica | B35: Macieira | C35: BRAVO DE ESMOLFE | D35: Permanente | F35: Novembro a dezembro | G35: Março a abril | H35: Agosto a setembro | S35: {=_xlfn.XLOOKUP(A35&B35,$K$2:$K$13&$L$2:$L$13,$J$2:$J$13)} -> 3 | T35: BRAVO DE ESMOLFE | U35: 34 | V35: =_xlfn.CONCAT(B35," ",C35) -> Macieira BRAVO DE ESMOLFE | W35: ="INSERT INTO Cultura(CulturaID, Variedade, EspecieVegetalID, EpocaSementeiraPlantacao, EpocaPoda, EpocaFloracao, EpocaColheita) VALUES ("&U35&", '"&T35&"', "&S35&", '"&E35&"', '"&F35&"', '"&G35&"', '"&H35&"');" -> INSERT INTO Cultura(CulturaID, Variedade, EspecieVegetalID, EpocaSementeiraPlantacao, EpocaPoda, EpocaFloracao, EpocaColheita) VALUES (34, 'BRAVO DE ESMOLFE', 3, '', 'Novembro a dezembro', 'Março a abril', 'Agosto a setembro');
A36: Malus domestica | B36: Macieira | C36: CASA NOVA DE ALCOBAÇA | D36: Permanente | F36: Novembro a dezembro | G36: Março a abril | H36: Agosto a setembro | S36: {=_xlfn.XLOOKUP(A36&B36,$K$2:$K$13&$L$2:$L$13,$J$2:$J$13)} -> 3 | T36: CASA NOVA DE ALCOBAÇA | U36: 35 | V36: =_xlfn.CONCAT(B36," ",C36) -> Macieira CASA NOVA DE ALCOBAÇA | W36: ="INSERT INTO Cultura(CulturaID, Variedade, EspecieVegetalID, EpocaSementeiraPlantacao, EpocaPoda, EpocaFloracao, EpocaColheita) VALUES ("&U36&", '"&T36&"', "&S36&", '"&E36&"', '"&F36&"', '"&G36&"', '"&H36&"');" -> INSERT INTO Cultura(CulturaID, Variedade, EspecieVegetalID, EpocaSementeiraPlantacao, EpocaPoda, EpocaFloracao, EpocaColheita) VALUES (35, 'CASA NOVA DE ALCOBAÇA', 3, '', 'Novembro a dezembro', 'Março a abril', 'Agosto a setembro');
A37: Malus domestica | B37: Macieira | C37: EROVAN | D37: Permanente | F37: Novembro a dezembro | G37: Março a abril | H37: Agosto a setembro | S37: {=_xlfn.XLOOKUP(A37&B37,$K$2:$K$13&$L$2:$L$13,$J$2:$J$13)} -> 3 | T37: EROVAN | U37: 36 | V37: =_xlfn.CONCAT(B37," ",C37) -> Macieira EROVAN | W37: ="INSERT INTO Cultura(CulturaID, Variedade, EspecieVegetalID, EpocaSementeiraPlantacao, EpocaPoda, EpocaFloracao, EpocaColheita) VALUES ("&U37&", '"&T37&"', "&S37&", '"&E37&"', '"&F37&"', '"&G37&"', '"&H37&"');" -> INSERT INTO Cultura(CulturaID, Variedade, EspecieVegetalID, EpocaSementeiraPlantacao, EpocaPoda, EpocaFloracao, EpocaColheita) VALUES (36, 'EROVAN', 3, '', 'Novembro a dezembro', 'Março a abril', 'Agosto a setembro');
A38: Malus domestica | B38: Macieira | C38: FUJI | D38: Permanente | F38: Novembro a dezembro | G38: Março a abril | H38: Agosto a setembro | S38: {=_xlfn.XLOOKUP(A38&B38,$K$2:$K$13&$L$2:$L$13,$J$2:$J$13)} -> 3 | T38: FUJI | U38: 37 | V38: =_xlfn.CONCAT(B38," ",C38) -> Macieira FUJI | W38: ="INSERT INTO Cultura(CulturaID, Variedade, EspecieVegetalID, EpocaSementeiraPlantacao, EpocaPoda, EpocaFloracao, EpocaColheita) VALUES ("&U38&", '"&T38&"', "&S38&", '"&E38&"', '"&F38&"', '"&G38&"', '"&H38&"');" -> INSERT INTO Cultura(CulturaID, Variedade, EspecieVegetalID, EpocaSementeiraPlantacao, EpocaPoda, EpocaFloracao, EpocaColheita) VALUES (37, 'FUJI', 3, '', 'Novembro a dezembro', 'Março a abril', 'Agosto a setembro');
A39: Malus domestica | B39: Macieira | C39: GRANNY SMITH | D39: Permanente | F39: Novembro a dezembro | G39: Março a abril | H39: Agosto a setembro | S39: {=_xlfn.XLOOKUP(A39&B39,$K$2:$K$13&$L$2:$L$13,$J$2:$J$13)} -> 3 | T39: GRANNY SMITH | U39: 38 | V39: =_xlfn.CONCAT(B39," ",C39) -> Macieira GRANNY SMITH | W39: ="INSERT INTO Cultura(CulturaID, Variedade, EspecieVegetalID, EpocaSementeiraPlantacao, EpocaPoda, EpocaFloracao, EpocaColheita) VALUES ("&U39&", '"&T39&"', "&S39&", '"&E39&"', '"&F39&"', '"&G39&"', '"&H39&"');" -> INSERT INTO Cultura(CulturaID, Variedade, EspecieVegetalID, EpocaSementeiraPlantacao, EpocaPoda, EpocaFloracao, EpocaColheita) VALUES (38, 'GRANNY SMITH', 3, '', 'Novembro a dezembro', 'Março a abril', 'Agosto a setembro');
A40: Malus domestica | B40: Macieira | C40: GOLDEN DELICIOUS | D40: Permanente | F40: Novembro a dezembro | G40: Março a abril | H40: Agosto a setembro | S40: {=_xlfn.XLOOKUP(A40&B40,$K$2:$K$13&$L$2:$L$13,$J$2:$J$13)} -> 3 | T40: GOLDEN DELICIOUS | U40: 39 | V40: =_xlfn.CONCAT(B40," ",C40) -> Macieira GOLDEN DELICIOUS | W40: ="INSERT INTO Cultura(CulturaID, Variedade, EspecieVegetalID, EpocaSementeiraPlantacao, EpocaPoda, EpocaFloracao, EpocaColheita) VALUES ("&U40&", '"&T40&"', "&S40&", '"&E40&"', '"&F40&"', '"&G40&"', '"&H40&"');" -> INSERT INTO Cultura(CulturaID, Variedade, EspecieVegetalID, EpocaSementeiraPlantacao, EpocaPoda, EpocaFloracao, EpocaColheita) VALUES (39, 'GOLDEN DELICIOUS', 3, '', 'Novembro a dezembro', 'Março a abril', 'Agosto a setembro');
...

Sheet Fator Produção
A1: Designação | B1: Fabricante | C1: Formato | D1: Tipo | E1: Aplicação | F1: C1 | G1: Perc. | H1: C2 | I1: Perc. | J1: C3 | K1: Perc. | L1: C4 | M1: Perc.
A2: Calda Bordalesa ASCENZA | B2: ASCENZA | C2: Pó molhável | D2: Fitofármaco | E2: Fungicida | F2: CU | G2: 0.2
A3: Enxofre Bayer 80 WG | B3: Bayer | C3: Pó molhável | D3: Fitofármaco | E3: Fungicida | F3: S | G3: 0.8
A4: Patentkali | B4: K+S | C4: Granulado | D4: Adubo | E4: Adubo solo | F4: K | G4: 0.249 | H4: Mg | I4: 0.06 | J4: S | K4: 0.176
A5: ESTA Kieserit | B5: K+S | C5: Granulado | D5: Adubo | E5: Adubo solo | F5: Mg | G5: 0.151 | H5: S | I5: 0.208
A6: EPSO Microtop | B6: K+S | C6: Granulado | D6: Adubo | E6: Adubo foliar+Fertirrega | F6: Mg | G6: 0.09 | H6: S | I6: 0.124 | J6: B | K6: 0.009 | L6: Mn | M6: 0.01
A7: EPSO Top | B7: K+S | C7: Granulado | D7: Adubo | E7: Adubo foliar | F7: Mg | G7: 0.096 | H7: S | I7: 0.13
A8: Biocal CaCo3 | B8: Biocal | C8: Granulado | D8: Corretor | E8: Correção solo | F8: CaCO3 | G8: 0.882 | H8: MgCO3 | I8: 0.019
A9: Biocal Composto | B9: Biocal | C9: Pó | D9: Corretor | E9: Correção solo | F9: CaCO3 | G9: 0.717 | H9: MgCO3 | I9: 0.148 | J9: MgO | K9: 0.079
A10: Sonata | B10: Bayer | C10: Líquido | D10: Fitofármaco | E10: Fungicida | F10: Bacillus pumilus | G10: 0.9774
A11: FLiPPER | B11: Bayer | C11: Emulsão de óleo em água | D11: Fitofármaco | E11: Insecticida | F11: Ácidos gordos (na forma de sais de potássio) | G11: 0.478
A12: Requiem Prime | B12: Bayer | C12: Líquido | D12: Fitofármaco | E12: Insecticida | F12: Terpenóides | G12: 0.1442
A14: FatorProducao
A15: NomeComercial | B15: FatorProducaoID | C15: FabricanteID | D15: FormatoID | E15: TipoFatorProducaoID
A16: {=_xlfn.UNIQUE(A2:A12)} -> Calda Bordalesa ASCENZA | B16: 1 | C16: {=_xlfn.XLOOKUP(B2,_xlfn.ANCHORARRAY($A$29),$B$16:$B$19,0,0)} -> 1 | D16: {=_xlfn.XLOOKUP(C2,_xlfn.ANCHORARRAY($A$35),$B$16:$B$20,0,0)} -> 1 | E16: {=_xlfn.XLOOKUP(D2,_xlfn.ANCHORARRAY($A$42),$B$16:$B$18,0,0)} -> 1 | F16: ="INSERT INTO FatorProdução(FatorProducaoID, NomeComercial, FabricanteID, FormatoID, TipoFatorProducaoID) VALUES ("&B16&", '"&A16&"', "&C16&", "&D16&", "&E16&");" -> INSERT INTO FatorProdução(FatorProducaoID, NomeComercial, FabricanteID, FormatoID, TipoFatorProducaoID) VALUES (1, 'Calda Bordalesa ASCENZA', 1, 1, 1); | O16: 5
A17: Enxofre Bayer 80 WG | B17: =B16+1 -> 2 | C17: {=_xlfn.XLOOKUP(B3,_xlfn.ANCHORARRAY($A$29),$B$16:$B$19,0,0)} -> 2 | D17: {=_xlfn.XLOOKUP(C3,_xlfn.ANCHORARRAY($A$35),$B$16:$B$20,0,0)} -> 1 | E17: {=_xlfn.XLOOKUP(D3,_xlfn.ANCHORARRAY($A$42),$B$16:$B$18,0,0)} -> 1 | F17: ="INSERT INTO FatorProdução(FatorProducaoID, NomeComercial, FabricanteID, FormatoID, TipoFatorProducaoID) VALUES ("&B17&", '"&A17&"', "&C17&", "&D17&", "&E17&");" -> INSERT INTO FatorProdução(FatorProducaoID, NomeComercial, FabricanteID, FormatoID, TipoFatorProducaoID) VALUES (2, 'Enxofre Bayer 80 WG', 2, 1, 1);
A18: Patentkali | B18: =B17+1 -> 3 | C18: {=_xlfn.XLOOKUP(B4,_xlfn.ANCHORARRAY($A$29),$B$16:$B$19,0,0)} -> 3 | D18: {=_xlfn.XLOOKUP(C4,_xlfn.ANCHORARRAY($A$35),$B$16:$B$20,0,0)} -> 2 | E18: {=_xlfn.XLOOKUP(D4,_xlfn.ANCHORARRAY($A$42),$B$16:$B$18,0,0)} -> 2 | F18: ="INSERT INTO FatorProdução(FatorProducaoID, NomeComercial, FabricanteID, FormatoID, TipoFatorProducaoID) VALUES ("&B18&", '"&A18&"', "&C18&", "&D18&", "&E18&");" -> INSERT INTO FatorProdução(FatorProducaoID, NomeComercial, FabricanteID, FormatoID, TipoFatorProducaoID) VALUES (3, 'Patentkali', 3, 2, 2);
A19: ESTA Kieserit | B19: =B18+1 -> 4 | C19: {=_xlfn.XLOOKUP(B5,_xlfn.ANCHORARRAY($A$29),$B$16:$B$19,0,0)} -> 3 | D19: {=_xlfn.XLOOKUP(C5,_xlfn.ANCHORARRAY($A$35),$B$16:$B$20,0,0)} -> 2 | E19: {=_xlfn.XLOOKUP(D5,_xlfn.ANCHORARRAY($A$42),$B$16:$B$18,0,0)} -> 2 | F19: ="INSERT INTO FatorProdução(FatorProducaoID, NomeComercial, FabricanteID, FormatoID, TipoFatorProducaoID) VALUES ("&B19&", '"&A19&"', "&C19&", "&D19&", "&E19&");" -> INSERT INTO FatorProdução(FatorProducaoID, NomeComercial, FabricanteID, FormatoID, TipoFatorProducaoID) VALUES (4, 'ESTA Kieserit', 3, 2, 2);
A20: EPSO Microtop | B20: =B19+1 -> 5 | C20: {=_xlfn.XLOOKUP(B6,_xlfn.ANCHORARRAY($A$29),$B$16:$B$19,0,0)} -> 3 | D20: {=_xlfn.XLOOKUP(C6,_xlfn.ANCHORARRAY($A$35),$B$16:$B$20,0,0)} -> 2 | E20: {=_xlfn.XLOOKUP(D6,_xlfn.ANCHORARRAY($A$42),$B$16:$B$18,0,0)} -> 2 | F20: ="INSERT INTO FatorProdução(FatorProducaoID, NomeComercial, FabricanteID, FormatoID, TipoFatorProducaoID) VALUES ("&B20&", '"&A20&"', "&C20&", "&D20&", "&E20&");" -> INSERT INTO FatorProdução(FatorProducaoID, NomeComercial, FabricanteID, FormatoID, TipoFatorProducaoID) VALUES (5, 'EPSO Microtop', 3, 2, 2);
A21: EPSO Top | B21: =B20+1 -> 6 | C21: {=_xlfn.XLOOKUP(B7,_xlfn.ANCHORARRAY($A$29),$B$16:$B$19,0,0)} -> 3 | D21: {=_xlfn.XLOOKUP(C7,_xlfn.ANCHORARRAY($A$35),$B$16:$B$20,0,0)} -> 2 | E21: {=_xlfn.XLOOKUP(D7,_xlfn.ANCHORARRAY($A$42),$B$16:$B$18,0,0)} -> 2 | F21: ="INSERT INTO FatorProdução(FatorProducaoID, NomeComercial, FabricanteID, FormatoID, TipoFatorProducaoID) VALUES ("&B21&", '"&A21&"', "&C21&", "&D21&", "&E21&");" -> INSERT INTO FatorProdução(FatorProducaoID, NomeComercial, FabricanteID, FormatoID, TipoFatorProducaoID) VALUES (6, 'EPSO Top', 3, 2, 2);
A22: Biocal CaCo3 | B22: =B21+1 -> 7 | C22: {=_xlfn.XLOOKUP(B8,_xlfn.ANCHORARRAY($A$29),$B$16:$B$19,0,0)} -> 4 | D22: {=_xlfn.XLOOKUP(C8,_xlfn.ANCHORARRAY($A$35),$B$16:$B$20,0,0)} -> 2 | E22: {=_xlfn.XLOOKUP(D8,_xlfn.ANCHORARRAY($A$42),$B$16:$B$18,0,0)} -> 3 | F22: ="INSERT INTO FatorProdução(FatorProducaoID, NomeComercial, FabricanteID, FormatoID, TipoFatorProducaoID) VALUES ("&B22&", '"&A22&"', "&C22&", "&D22&", "&E22&");" -> INSERT INTO FatorProdução(FatorProducaoID, NomeComercial, FabricanteID, FormatoID, TipoFatorProducaoID) VALUES (7, 'Biocal CaCo3', 4, 2, 3);
A23: Biocal Composto | B23: =B22+1 -> 8 | C23: {=_xlfn.XLOOKUP(B9,_xlfn.ANCHORARRAY($A$29),$B$16:$B$19,0,0)} -> 4 | D23: {=_xlfn.XLOOKUP(C9,_xlfn.ANCHORARRAY($A$35),$B$16:$B$20,0,0)} -> 3 | E23: {=_xlfn.XLOOKUP(D9,_xlfn.ANCHORARRAY($A$42),$B$16:$B$18,0,0)} -> 3 | F23: ="INSERT INTO FatorProdução(FatorProducaoID, NomeComercial, FabricanteID, FormatoID, TipoFatorProducaoID) VALUES ("&B23&", '"&A23&"', "&C23&", "&D23&", "&E23&");" -> INSERT INTO FatorProdução(FatorProducaoID, NomeComercial, FabricanteID, FormatoID, TipoFatorProducaoID) VALUES (8, 'Biocal Composto', 4, 3, 3);
A24: Sonata | B24: =B23+1 -> 9 | C24: {=_xlfn.XLOOKUP(B10,_xlfn.ANCHORARRAY($A$29),$B$16:$B$19,0,0)} -> 2 | D24: {=_xlfn.XLOOKUP(C10,_xlfn.ANCHORARRAY($A$35),$B$16:$B$20,0,0)} -> 4 | E24: {=_xlfn.XLOOKUP(D10,_xlfn.ANCHORARRAY($A$42),$B$16:$B$18,0,0)} -> 1 | F24: ="INSERT INTO FatorProdução(FatorProducaoID, NomeComercial, FabricanteID, FormatoID, TipoFatorProducaoID) VALUES ("&B24&", '"&A24&"', "&C24&", "&D24&", "&E24&");" -> INSERT INTO FatorProdução(FatorProducaoID, NomeComercial, FabricanteID, FormatoID, TipoFatorProducaoID) VALUES (9, 'Sonata', 2, 4, 1);
A25: FLiPPER | B25: =B24+1 -> 10 | C25: {=_xlfn.XLOOKUP(B11,_xlfn.ANCHORARRAY($A$29),$B$16:$B$19,0,0)} -> 2 | D25: {=_xlfn.XLOOKUP(C11,_xlfn.ANCHORARRAY($A$35),$B$16:$B$20,0,0)} -> 5 | E25: {=_xlfn.XLOOKUP(D11,_xlfn.ANCHORARRAY($A$42),$B$16:$B$18,0,0)} -> 1 | F25: ="INSERT INTO FatorProdução(FatorProducaoID, NomeComercial, FabricanteID, FormatoID, TipoFatorProducaoID) VALUES ("&B25&", '"&A25&"', "&C25&", "&D25&", "&E25&");" -> INSERT INTO FatorProdução(FatorProducaoID, NomeComercial, FabricanteID, FormatoID, TipoFatorProducaoID) VALUES (10, 'FLiPPER ', 2, 5, 1);
A26: Requiem Prime | B26: =B25+1 -> 11 | C26: {=_xlfn.XLOOKUP(B12,_xlfn.ANCHORARRAY($A$29),$B$16:$B$19,0,0)} -> 2 | D26: {=_xlfn.XLOOKUP(C12,_xlfn.ANCHORARRAY($A$35),$B$16:$B$20,0,0)} -> 4 | E26: {=_xlfn.XLOOKUP(D12,_xlfn.ANCHORARRAY($A$42),$B$16:$B$18,0,0)} -> 1 | F26: ="INSERT INTO FatorProdução(FatorProducaoID, NomeComercial, FabricanteID, FormatoID, TipoFatorProducaoID) VALUES ("&B26&", '"&A26&"', "&C26&", "&D26&", "&E26&");" -> INSERT INTO FatorProdução(FatorProducaoID, NomeComercial, FabricanteID, FormatoID, TipoFatorProducaoID) VALUES (11, 'Requiem Prime', 2, 4, 1);
A28: Fabricante
A29: {=_xlfn.UNIQUE(B2:B12)} -> ASCENZA | B29: ="INSERT INTO Fabricante(FabricanteID, DesignacaoFabricante) VALUES ("&B16&", '"&A29&"');" -> INSERT INTO Fabricante(FabricanteID, DesignacaoFabricante) VALUES (1, 'ASCENZA');
A30: Bayer | B30: ="INSERT INTO Fabricante(FabricanteID, DesignacaoFabricante) VALUES ("&B17&", '"&A30&"');" -> INSERT INTO Fabricante(FabricanteID, DesignacaoFabricante) VALUES (2, 'Bayer'); | F30: 1
A31: K+S | B31: ="INSERT INTO Fabricante(FabricanteID, DesignacaoFabricante) VALUES ("&B18&", '"&A31&"');" -> INSERT INTO Fabricante(FabricanteID, DesignacaoFabricante) VALUES (3, 'K+S');
A32: Biocal | B32: ="INSERT INTO Fabricante(FabricanteID, DesignacaoFabricante) VALUES ("&B19&", '"&A32&"');" -> INSERT INTO Fabricante(FabricanteID, DesignacaoFabricante) VALUES (4, 'Biocal');
A34: Formato
A35: {=_xlfn.UNIQUE(C2:C12)} -> Pó molhável | B35: ="INSERT INTO Formato(FormatoID, DescricaoFormato) VALUES ("&B16&", '"&A35&"');" -> INSERT INTO Formato(FormatoID, DescricaoFormato) VALUES (1, 'Pó molhável'); | F35: 2
A36: Granulado | B36: ="INSERT INTO Formato(FormatoID, DescricaoFormato) VALUES ("&B17&", '"&A36&"');" -> INSERT INTO Formato(FormatoID, DescricaoFormato) VALUES (2, 'Granulado');
A37: Pó | B37: ="INSERT INTO Formato(FormatoID, DescricaoFormato) VALUES ("&B18&", '"&A37&"');" -> INSERT INTO Formato(FormatoID, DescricaoFormato) VALUES (3, 'Pó');
A38: Líquido | B38: ="INSERT INTO Formato(FormatoID, DescricaoFormato) VALUES ("&B19&", '"&A38&"');" -> INSERT INTO Formato(FormatoID, DescricaoFormato) VALUES (4, 'Líquido');
A39: Emulsão de óleo em água | B39: ="INSERT INTO Formato(FormatoID, DescricaoFormato) VALUES ("&B20&", '"&A39&"');" -> INSERT INTO Formato(FormatoID, DescricaoFormato) VALUES (5, 'Emulsão de óleo em água');
A41: TipoFatorProducao
A42: {=_xlfn.UNIQUE(D2:D12)} -> Fitofármaco | B42: ="INSERT INTO TipoFatorProducao(TipoFatorProducaoID, DescricaoTipoFatorProducao) VALUES ("&B16&", '"&A42&"');" -> INSERT INTO TipoFatorProducao(TipoFatorProducaoID, DescricaoTipoFatorProducao) VALUES (1, 'Fitofármaco'); | G42: 3
A43: Adubo | B43: ="INSERT INTO TipoFatorProducao(TipoFatorProducaoID, DescricaoTipoFatorProducao) VALUES ("&B17&", '"&A43&"');" -> INSERT INTO TipoFatorProducao(TipoFatorProducaoID, DescricaoTipoFatorProducao) VALUES (2, 'Adubo');
A44: Corretor | B44: ="INSERT INTO TipoFatorProducao(TipoFatorProducaoID, DescricaoTipoFatorProducao) VALUES ("&B18&", '"&A44&"');" -> INSERT INTO TipoFatorProducao(TipoFatorProducaoID, DescricaoTipoFatorProducao) VALUES (3, 'Corretor');
...

Sheet Exploração agrícola
A1: ID | B1: Tipo | C1: Designação | D1: Dimensão | E1: Unidade | F1: UnidadeID
A2: 101 | B2: Parcela | C2: Campo da bouça | D2: 1.2 | E2: ha | F2: =_xlfn.XLOOKUP(E2,Unidades!$C$3:$C$8,Unidades!$B$3:$B$8,0,0) -> 4 | I2: ="INSERT INTO Parcela(ParcelaID, Designacao, Area, UnidadeID) VALUES ("&A2&", '"&C2&"', "&SUBSTITUTE(D2,",",".")&", "&F2&" );" -> INSERT INTO Parcela(ParcelaID, Designacao, Area, UnidadeID) VALUES (101, 'Campo da bouça', 1.2, 4 ); | J2: 2
A3: 102 | B3: Parcela | C3: Campo grande | D3: 3 | E3: ha | F3: =_xlfn.XLOOKUP(E3,Unidades!$C$3:$C$8,Unidades!$B$3:$B$8,0,0) -> 4 | I3: ="INSERT INTO Parcela(ParcelaID, Designacao, Area, UnidadeID) VALUES ("&A3&", '"&C3&"', "&SUBSTITUTE(D3,",",".")&", "&F3&" );" -> INSERT INTO Parcela(ParcelaID, Designacao, Area, UnidadeID) VALUES (102, 'Campo grande', 3, 4 );
A4: 103 | B4: Parcela | C4: Campo do poço | D4: 1.5 | E4: ha | F4: =_xlfn.XLOOKUP(E4,Unidades!$C$3:$C$8,Unidades!$B$3:$B$8,0,0) -> 4 | I4: ="INSERT INTO Parcela(ParcelaID, Designacao, Area, UnidadeID) VALUES ("&A4&", '"&C4&"', "&SUBSTITUTE(D4,",",".")&", "&F4&" );" -> INSERT INTO Parcela(ParcelaID, Designacao, Area, UnidadeID) VALUES (103, 'Campo do poço', 1.5, 4 );
A5: 104 | B5: Parcela | C5: Lameiro da ponte | D5: 0.8 | E5: ha | F5: =_xlfn.XLOOKUP(E5,Unidades!$C$3:$C$8,Unidades!$B$3:$B$8,0,0) -> 4 | I5: ="INSERT INTO Parcela(ParcelaID, Designacao, Area, UnidadeID) VALUES ("&A5&", '"&C5&"', "&SUBSTITUTE(D5,",",".")&", "&F5&" );" -> INSERT INTO Parcela(ParcelaID, Designacao, Area, UnidadeID) VALUES (104, 'Lameiro da ponte', 0.8, 4 );
A6: 105 | B6: Parcela | C6: Lameiro do moinho | D6: 1.1 | E6: ha | F6: =_xlfn.XLOOKUP(E6,Unidades!$C$3:$C$8,Unidades!$B$3:$B$8,0,0) -> 4 | I6: ="INSERT INTO Parcela(ParcelaID, Designacao, Area, UnidadeID) VALUES ("&A6&", '"&C6&"', "&SUBSTITUTE(D6,",",".")&", "&F6&" );" -> INSERT INTO Parcela(ParcelaID, Designacao, Area, UnidadeID) VALUES (105, 'Lameiro do moinho', 1.1, 4 );
A7: 106 | B7: Parcela | C7: Horta nova | D7: 0.3 | E7: ha | F7: =_xlfn.XLOOKUP(E7,Unidades!$C$3:$C$8,Unidades!$B$3:$B$8,0,0) -> 4 | I7: ="INSERT INTO Parcela(ParcelaID, Designacao, Area, UnidadeID) VALUES ("&A7&", '"&C7&"', "&SUBSTITUTE(D7,",",".")&", "&F7&" );" -> INSERT INTO Parcela(ParcelaID, Designacao, Area, UnidadeID) VALUES (106, 'Horta nova', 0.3, 4 );
A8: 107 | B8: Parcela | C8: Vinha | D8: 2 | E8: ha | F8: =_xlfn.XLOOKUP(E8,Unidades!$C$3:$C$8,Unidades!$B$3:$B$8,0,0) -> 4 | G8: TipoID | I8: ="INSERT INTO Parcela(ParcelaID, Designacao, Area, UnidadeID) VALUES ("&A8&", '"&C8&"', "&SUBSTITUTE(D8,",",".")&", "&F8&" );" -> INSERT INTO Parcela(ParcelaID, Designacao, Area, UnidadeID) VALUES (107, 'Vinha', 2, 4 );
A9: 201 | B9: Armazém | C9: Espigueiro | D9: 600 | E9: m2 | F9: =_xlfn.XLOOKUP(E9,Unidades!$C$3:$C$8,Unidades!$B$3:$B$8,0,0) -> 5 | G9: =_xlfn.XLOOKUP(B9,$A$18:$A$21,$B$18:$B$21,0) -> 1 | I9: ="INSERT INTO Edificio(EdificioID, DesignacaoEdificio, Area, TipoEdificioID, UnidadeID) VALUES ("&A9&", '"&C9&"', "&IF(D9=0,0,D9)&", "&G9&", "&F9&");" -> INSERT INTO Edificio(EdificioID, DesignacaoEdificio, Area, TipoEdificioID, UnidadeID) VALUES (201, 'Espigueiro', 600, 1, 5); | J9: 3
A10: 202 | B10: Armazém | C10: Armazém novo | D10: 800 | E10: m2 | F10: =_xlfn.XLOOKUP(E10,Unidades!$C$3:$C$8,Unidades!$B$3:$B$8,0,0) -> 5 | G10: =_xlfn.XLOOKUP(B10,$A$18:$A$21,$B$18:$B$21,0) -> 1 | I10: ="INSERT INTO Edificio(EdificioID, DesignacaoEdificio, Area, TipoEdificioID, UnidadeID) VALUES ("&A10&", '"&C10&"', "&IF(D10=0,0,D10)&", "&G10&", "&F10&");" -> INSERT INTO Edificio(EdificioID, DesignacaoEdificio, Area, TipoEdificioID, UnidadeID) VALUES (202, 'Armazém novo', 800, 1, 5);
A11: 203 | B11: Garagem | C11: Armazém grande | D11: 900 | E11: m2 | F11: =_xlfn.XLOOKUP(E11,Unidades!$C$3:$C$8,Unidades!$B$3:$B$8,0,0) -> 5 | G11: =_xlfn.XLOOKUP(B11,$A$18:$A$21,$B$18:$B$21,0) -> 2 | I11: ="INSERT INTO Edificio(EdificioID, DesignacaoEdificio, Area, TipoEdificioID, UnidadeID) VALUES ("&A11&", '"&C11&"', "&IF(D11=0,0,D11)&", "&G11&", "&F11&");" -> INSERT INTO Edificio(EdificioID, DesignacaoEdificio, Area, TipoEdificioID, UnidadeID) VALUES (203, 'Armazém grande', 900, 2, 5);
A12: 250 | B12: Moinho | C12: Moinho | G12: =_xlfn.XLOOKUP(B12,$A$18:$A$21,$B$18:$B$21,0) -> 3 | I12: ="INSERT INTO Edificio(EdificioID, DesignacaoEdificio, Area, TipoEdificioID, UnidadeID) VALUES ("&A12&", '"&C12&"', "&IF(D12=0,0,D12)&", "&G12&", "&IF(F12="","''",0)&");" -> INSERT INTO Edificio(EdificioID, DesignacaoEdificio, Area, TipoEdificioID, UnidadeID) VALUES (250, 'Moinho', 0, 3, '');
A13: 301 | B13: Rega | C13: Tanque do campo grande | D13: 18 | E13: m3 | F13: =_xlfn.XLOOKUP(E13,Unidades!$C$3:$C$8,Unidades!$B$3:$B$8,0,0) -> 2 | G13: =_xlfn.XLOOKUP(B13,$A$18:$A$21,$B$18:$B$21,0) -> 4 | I13: ="INSERT INTO Edificio(EdificioID, DesignacaoEdificio, Area, TipoEdificioID, UnidadeID) VALUES ("&A13&", '"&C13&"', "&IF(D13=0,0,D13)&", "&G13&", "&F13&");" -> INSERT INTO Edificio(EdificioID, DesignacaoEdificio, Area, TipoEdificioID, UnidadeID) VALUES (301, 'Tanque do campo grande', 18, 4, 2);
A14: 302 | B14: Rega | C14: Poço da bouça | D14: 35 | E14: m3 | F14: =_xlfn.XLOOKUP(E14,Unidades!$C$3:$C$8,Unidades!$B$3:$B$8,0,0) -> 2 | G14: =_xlfn.XLOOKUP(B14,$A$18:$A$21,$B$18:$B$21,0) -> 4 | I14: ="INSERT INTO Edificio(EdificioID, DesignacaoEdificio, Area, TipoEdificioID, UnidadeID) VALUES ("&A14&", '"&C14&"', "&IF(D14=0,0,D14)&", "&G14&", "&F14&");" -> INSERT INTO Edificio(EdificioID, DesignacaoEdificio, Area, TipoEdificioID, UnidadeID) VALUES (302, 'Poço da bouça', 35, 4, 2);
A16: TipoDeEdificio
A17: Designacao | B17: ID
A18: {=_xlfn.UNIQUE(B9:B14)} -> Armazém | B18: 1
A19: Garagem | B19: =B18+1 -> 2
A20: Moinho | B20: =B19+1 -> 3
A21: Rega | B21: =B20+1 -> 4
A22: ="INSERT INTO TipoEdificio(TipoEdificioID, DesignacaoTipoEdificio) VALUES ("&B18&", '"&A18&"');" -> INSERT INTO TipoEdificio(TipoEdificioID, DesignacaoTipoEdificio) VALUES (1, 'Armazém'); | H22: 1
A23: ="INSERT INTO TipoEdificio(TipoEdificioID, DesignacaoTipoEdificio) VALUES ("&B19&", '"&A19&"');" -> INSERT INTO TipoEdificio(TipoEdificioID, DesignacaoTipoEdificio) VALUES (2, 'Garagem');
A24: ="INSERT INTO TipoEdificio(TipoEdificioID, DesignacaoTipoEdificio) VALUES ("&B20&", '"&A20&"');" -> INSERT INTO TipoEdificio(TipoEdificioID, DesignacaoTipoEdificio) VALUES (3, 'Moinho');
A25: ="INSERT INTO TipoEdificio(TipoEdificioID, DesignacaoTipoEdificio) VALUES ("&B21&", '"&A21&"');" -> INSERT INTO TipoEdificio(TipoEdificioID, DesignacaoTipoEdificio) VALUES (4, 'Rega');

Sheet Culturas
A1: ID | B1: Parcela | C1: Cultura | D1: Tipo | E1: Data Inicial | F1: Data Final | G1: Quantidade | H1: Unidades | I1: UnidadeID | J1: CulturaID | K1: CultivoID | L1: CREATE TABLE Cultivo (CultivoID number(10) NOT NULL, CulturaID number(10) NOT NULL, ParcelaID number(10) NOT NULL, DataInicio date NOT NULL, DataFim date, Quantidade number(10) NOT NULL, UnidadeID number(10), PRIMARY KEY (CultivoID));
A2: 101 | B2: Campo da bouça | C2: Tremoço Amarelo | D2: Temporária | E2: 44114 | F2: 44285 | G2: 1.1 | H2: ha | I2: =_xlfn.XLOOKUP(H2,Unidades!$C$3:$C$8,Unidades!$B$3:$B$8,0,0) -> 4 | J2: {=_xlfn.XLOOKUP(C2:C28,Plantas!$V$2:$V$96,Plantas!U2:U96,-1,0)} -> 80 | K2: 1 | L2: ="INSERT INTO Cultivo(CultivoID, CulturaID, ParcelaID, DataInicio, DataFim, Quantidade, UnidadeID) VALUES ("&K2&", "&J2&", "&A2&",TO_DATE('"&TEXT(E2,"dd/mm/aaaa")&"','dd/mm/yyyy'), TO_DATE('"&IF(F2<>"",TEXT(F2,"dd/mm/aaaa"),"")&"', 'dd/mm/yyyy'), "&SUBSTITUTE(G2,",",".")&", "&I2&");" -> INSERT INTO Cultivo(CultivoID, CulturaID, ParcelaID, DataInicio, DataFim, Quantidade, UnidadeID) VALUES (1, 80, 101,TO_DATE('10/10/2020','dd/mm/yyyy'), TO_DATE('30/03/2021', 'dd/mm/yyyy'), 1.1, 4);
A3: 101 | B3: Campo da bouça | C3: Milho Doce Golden Bantam | D3: Temporária | E3: 44296 | F3: 44420 | G3: 0.9 | H3: ha | I3: =_xlfn.XLOOKUP(H3,Unidades!$C$3:$C$8,Unidades!$B$3:$B$8,0,0) -> 4 | J3: 83 | K3: =K2+1 -> 2 | L3: ="INSERT INTO Cultivo(CultivoID, CulturaID, ParcelaID, DataInicio, DataFim, Quantidade, UnidadeID) VALUES ("&K3&", "&J3&", "&A3&",TO_DATE('"&TEXT(E3,"dd/mm/aaaa")&"','dd/mm/yyyy'), TO_DATE('"&IF(F3<>"",TEXT(F3,"dd/mm/aaaa"),"")&"', 'dd/mm/yyyy'), "&SUBSTITUTE(G3,",",".")&", "&I3&");" -> INSERT INTO Cultivo(CultivoID, CulturaID, ParcelaID, DataInicio, DataFim, Quantidade, UnidadeID) VALUES (2, 83, 101,TO_DATE('10/04/2021','dd/mm/yyyy'), TO_DATE('12/08/2021', 'dd/mm/yyyy'), 0.9, 4);
A4: 101 | B4: Campo da bouça | C4: Tremoço Amarelo | D4: Temporária | E4: 44472 | F4: 44656 | G4: 1.1 | H4: ha | I4: =_xlfn.XLOOKUP(H4,Unidades!$C$3:$C$8,Unidades!$B$3:$B$8,0,0) -> 4 | J4: 80 | K4: =K3+1 -> 3 | L4: ="INSERT INTO Cultivo(CultivoID, CulturaID, ParcelaID, DataInicio, DataFim, Quantidade, UnidadeID) VALUES ("&K4&", "&J4&", "&A4&",TO_DATE('"&TEXT(E4,"dd/mm/aaaa")&"','dd/mm/yyyy'), TO_DATE('"&IF(F4<>"",TEXT(F4,"dd/mm/aaaa"),"")&"', 'dd/mm/yyyy'), "&SUBSTITUTE(G4,",",".")&", "&I4&");" -> INSERT INTO Cultivo(CultivoID, CulturaID, ParcelaID, DataInicio, DataFim, Quantidade, UnidadeID) VALUES (3, 80, 101,TO_DATE('03/10/2021','dd/mm/yyyy'), TO_DATE('05/04/2022', 'dd/mm/yyyy'), 1.1, 4);
A5: 101 | B5: Campo da bouça | C5: Milho Doce Golden Bantam | D5: Temporária | E5: 44666 | F5: 44794 | G5: 0.9 | H5: ha | I5: =_xlfn.XLOOKUP(H5,Unidades!$C$3:$C$8,Unidades!$B$3:$B$8,0,0) -> 4 | J5: 83 | K5: =K4+1 -> 4 | L5: ="INSERT INTO Cultivo(CultivoID, CulturaID, ParcelaID, DataInicio, DataFim, Quantidade, UnidadeID) VALUES ("&K5&", "&J5&", "&A5&",TO_DATE('"&TEXT(E5,"dd/mm/aaaa")&"','dd/mm/yyyy'), TO_DATE('"&IF(F5<>"",TEXT(F5,"dd/mm/aaaa"),"")&"', 'dd/mm/yyyy'), "&SUBSTITUTE(G5,",",".")&", "&I5&");" -> INSERT INTO Cultivo(CultivoID, CulturaID, ParcelaID, DataInicio, DataFim, Quantidade, UnidadeID) VALUES (4, 83, 101,TO_DATE('15/04/2022','dd/mm/yyyy'), TO_DATE('21/08/2022', 'dd/mm/yyyy'), 0.9, 4);
A6: 103 | B6: Campo do poço | C6: Milho MAS 24.C | D6: Temporária | E6: 43926 | F6: 44063 | G6: 1.2 | H6: ha | I6: =_xlfn.XLOOKUP(H6,Unidades!$C$3:$C$8,Unidades!$B$3:$B$8,0,0) -> 4 | J6: 82 | K6: =K5+1 -> 5 | L6: ="INSERT INTO Cultivo(CultivoID, CulturaID, ParcelaID, DataInicio, DataFim, Quantidade, UnidadeID) VALUES ("&K6&", "&J6&", "&A6&",TO_DATE('"&TEXT(E6,"dd/mm/aaaa")&"','dd/mm/yyyy'), TO_DATE('"&IF(F6<>"",TEXT(F6,"dd/mm/aaaa"),"")&"', 'dd/mm/yyyy'), "&SUBSTITUTE(G6,",",".")&", "&I6&");" -> INSERT INTO Cultivo(CultivoID, CulturaID, ParcelaID, DataInicio, DataFim, Quantidade, UnidadeID) VALUES (5, 82, 103,TO_DATE('05/04/2020','dd/mm/yyyy'), TO_DATE('20/08/2020', 'dd/mm/yyyy'), 1.2, 4);
A7: 103 | B7: Campo do poço | C7: Tremoço Amarelo | D7: Temporária | E7: 44116 | F7: 44270 | G7: 1.3 | H7: ha | I7: =_xlfn.XLOOKUP(H7,Unidades!$C$3:$C$8,Unidades!$B$3:$B$8,0,0) -> 4 | J7: 80 | K7: =K6+1 -> 6 | L7: ="INSERT INTO Cultivo(CultivoID, CulturaID, ParcelaID, DataInicio, DataFim, Quantidade, UnidadeID) VALUES ("&K7&", "&J7&", "&A7&",TO_DATE('"&TEXT(E7,"dd/mm/aaaa")&"','dd/mm/yyyy'), TO_DATE('"&IF(F7<>"",TEXT(F7,"dd/mm/aaaa"),"")&"', 'dd/mm/yyyy'), "&SUBSTITUTE(G7,",",".")&", "&I7&");" -> INSERT INTO Cultivo(CultivoID, CulturaID, ParcelaID, DataInicio, DataFim, Quantidade, UnidadeID) VALUES (6, 80, 103,TO_DATE('12/10/2020','dd/mm/yyyy'), TO_DATE('15/03/2021', 'dd/mm/yyyy'), 1.3, 4);
A8: 103 | B8: Campo do poço | C8: Milho MAS 24.C | D8: Temporária | E8: 44289 | F8: 44433 | G8: 1.2 | H8: ha | I8: =_xlfn.XLOOKUP(H8,Unidades!$C$3:$C$8,Unidades!$B$3:$B$8,0,0) -> 4 | J8: 82 | K8: =K7+1 -> 7 | L8: ="INSERT INTO Cultivo(CultivoID, CulturaID, ParcelaID, DataInicio, DataFim, Quantidade, UnidadeID) VALUES ("&K8&", "&J8&", "&A8&",TO_DATE('"&TEXT(E8,"dd/mm/aaaa")&"','dd/mm/yyyy'), TO_DATE('"&IF(F8<>"",TEXT(F8,"dd/mm/aaaa"),"")&"', 'dd/mm/yyyy'), "&SUBSTITUTE(G8,",",".")&", "&I8&");" -> INSERT INTO Cultivo(CultivoID, CulturaID, ParcelaID, DataInicio, DataFim, Quantidade, UnidadeID) VALUES (7, 82, 103,TO_DATE('03/04/2021','dd/mm/yyyy'), TO_DATE('25/08/2021', 'dd/mm/yyyy'), 1.2, 4);
A9: 103 | B9: Campo do poço | C9: Tremoço Amarelo | D9: Temporária | E9: 44475 | F9: 44639 | G9: 1.3 | H9: ha | I9: =_xlfn.XLOOKUP(H9,Unidades!$C$3:$C$8,Unidades!$B$3:$B$8,0,0) -> 4 | J9: 80 | K9: =K8+1 -> 8 | L9: ="INSERT INTO Cultivo(CultivoID, CulturaID, ParcelaID, DataInicio, DataFim, Quantidade, UnidadeID) VALUES ("&K9&", "&J9&", "&A9&",TO_DATE('"&TEXT(E9,"dd/mm/aaaa")&"','dd/mm/yyyy'), TO_DATE('"&IF(F9<>"",TEXT(F9,"dd/mm/aaaa"),"")&"', 'dd/mm/yyyy'), "&SUBSTITUTE(G9,",",".")&", "&I9&");" -> INSERT INTO Cultivo(CultivoID, CulturaID, ParcelaID, DataInicio, DataFim, Quantidade, UnidadeID) VALUES (8, 80, 103,TO_DATE('06/10/2021','dd/mm/yyyy'), TO_DATE('19/03/2022', 'dd/mm/yyyy'), 1.3, 4);
A10: 103 | B10: Campo do poço | C10: Milho MAS 24.C | D10: Temporária | E10: 44659 | F10: 44791 | G10: 1.2 | H10: ha | I10: =_xlfn.XLOOKUP(H10,Unidades!$C$3:$C$8,Unidades!$B$3:$B$8,0,0) -> 4 | J10: 82 | K10: =K9+1 -> 9 | L10: ="INSERT INTO Cultivo(CultivoID, CulturaID, ParcelaID, DataInicio, DataFim, Quantidade, UnidadeID) VALUES ("&K10&", "&J10&", "&A10&",TO_DATE('"&TEXT(E10,"dd/mm/aaaa")&"','dd/mm/yyyy'), TO_DATE('"&IF(F10<>"",TEXT(F10,"dd/mm/aaaa"),"")&"', 'dd/mm/yyyy'), "&SUBSTITUTE(G10,",",".")&", "&I10&");" -> INSERT INTO Cultivo(CultivoID, CulturaID, ParcelaID, DataInicio, DataFim, Quantidade, UnidadeID) VALUES (9, 82, 103,TO_DATE('08/04/2022','dd/mm/yyyy'), TO_DATE('18/08/2022', 'dd/mm/yyyy'), 1.2, 4);
A11: 103 | B11: Campo do poço | C11: Tremoço Amarelo | D11: Temporária | E11: 44846 | F11: 45005 | G11: 1.3 | H11: ha | I11: =_xlfn.XLOOKUP(H11,Unidades!$C$3:$C$8,Unidades!$B$3:$B$8,0,0) -> 4 | J11: 80 | K11: =K10+1 -> 10 | L11: ="INSERT INTO Cultivo(CultivoID, CulturaID, ParcelaID, DataInicio, DataFim, Quantidade, UnidadeID) VALUES ("&K11&", "&J11&", "&A11&",TO_DATE('"&TEXT(E11,"dd/mm/aaaa")&"','dd/mm/yyyy'), TO_DATE('"&IF(F11<>"",TEXT(F11,"dd/mm/aaaa"),"")&"', 'dd/mm/yyyy'), "&SUBSTITUTE(G11,",",".")&", "&I11&");" -> INSERT INTO Cultivo(CultivoID, CulturaID, ParcelaID, DataInicio, DataFim, Quantidade, UnidadeID) VALUES (10, 80, 103,TO_DATE('12/10/2022','dd/mm/yyyy'), TO_DATE('20/03/2023', 'dd/mm/yyyy'), 1.3, 4);
A12: 102 | B12: Campo Grande | C12: Oliveira Galega | D12: Permanente | E12: 42649 | G12: 30 | H12: un | I12: =_xlfn.XLOOKUP(H12,Unidades!$C$3:$C$8,Unidades!$B$3:$B$8,0,0) -> 1 | J12: 92 | K12: =K11+1 -> 11 | L12: ="INSERT INTO Cultivo(CultivoID, CulturaID, ParcelaID, DataInicio, DataFim, Quantidade, UnidadeID) VALUES ("&K12&", "&J12&", "&A12&",TO_DATE('"&TEXT(E12,"dd/mm/aaaa")&"','dd/mm/yyyy'), TO_DATE('"&IF(F12<>"",TEXT(F12,"dd/mm/aaaa"),"")&"', 'dd/mm/yyyy'), "&SUBSTITUTE(G12,",",".")&", "&I12&");" -> INSERT INTO Cultivo(CultivoID, CulturaID, ParcelaID, DataInicio, DataFim, Quantidade, UnidadeID) VALUES (11, 92, 102,TO_DATE('06/10/2016','dd/mm/yyyy'), TO_DATE('', 'dd/mm/yyyy'), 30, 1);
